<?xml version="1.0" encoding="utf-8"?>
<!-- This URDF was automatically created by SolidWorks to URDF Exporter! Originally created by Stephen Brawner (brawner@gmail.com) 
     Commit Version: 1.5.1-0-g916b5db  Build Version: 1.5.7152.31018
     For more information, please see http://wiki.ros.org/sw_urdf_exporter -->
<robot
  name="orochi7" xmlns:xacro="http://ros.org/wiki/xacro">

<!-- ########### Defining the colors used in this robot ########### -->

  <material name="White">
      <color rgba="0.898039215686275 0.917647058823529 0.929411764705882 1"/>
  </material>

<!-- ##########################base_link########################## -->
  <link name="dummy">
    </link>
  <link
    name="base_link">
    <inertial>
      <origin
        xyz="0 0 0.01"
        rpy="0 0 0" />
      <mass
        value="12.8" />
      <inertia
        ixx="0.683093333333333"
        ixy="0"
        ixz="0"
        iyy="0.683093333333333"
        iyz="0"
        izz="1.36533333333333" />
    </inertial>

    <visual>
      <origin
        xyz="0 0 0"
        rpy="0 0 0" />
      <geometry>
        <mesh
          filename="package://orochi7/meshes/base_link.STL" />
      </geometry>
      <material
        name="">
        <color
          rgba="1 1 1 1" />
      </material>
    </visual>
    <collision>
      <origin
        xyz="0 0 0"
        rpy="0 0 0" />
      <geometry>
        <mesh
          filename="package://orochi7/meshes/base_link.STL" />
      </geometry>
    </collision>
  </link>

  <joint name="dummy_joint" type="fixed">
    <parent link="dummy"/>
    <child link="base_link"/>
  </joint>
<!-- ##########################link_0########################## -->

  <link
    name="Link_0">
    <inertial>
      <origin
        xyz="2.2136457538879E-08 -2.79407750550348E-07 0.0924156438654813"
        rpy="0 0 0" />
      <mass
        value="1.88014486866152" />
      <inertia
        ixx="0.0151317721890805"
        ixy="1.2237952342225E-08"
        ixz="2.08088296155032E-09"
        iyy="0.0151316127478672"
        iyz="-2.626438310439E-08"
        izz="0.010038350425731" />
    </inertial>
    <visual>
      <origin
        xyz="0 0 0"
        rpy="0 0 0" />
      <geometry>
        <mesh
          filename="package://orochi7/meshes/Link_0.STL" />
      </geometry>
      <material
        name="">
        <color
          rgba="0.898039215686275 0.917647058823529 0.929411764705882 1" />
      </material>
    </visual>
    <collision>
      <origin
        xyz="0 0 0"
        rpy="0 0 0" />
      <geometry>
        <mesh
          filename="package://orochi7/meshes/Link_0.STL" />
      </geometry>
    </collision>
  </link>
  <joint
    name="joint_0"
    type="fixed">
    <origin
      xyz="0 0 0.02"
      rpy="0 0 0" />
    <parent
      link="base_link" />
    <child
      link="Link_0" />
    <axis
      xyz="0 0 0" />
  </joint>

<!-- ##########################Link_1########################## -->

  <link
    name="Link_1">
    <inertial>
      <origin
        xyz="0.0228471602671468 0.000500609688309121 0.0788576426309777"
        rpy="0 0 0" />
      <mass
        value="2.51197128388461" />
      <inertia
        ixx="0.012008081154807"
        ixy="-2.56915293947424E-05"
        ixz="-0.00152433945966359"
        iyy="0.0101247306598904"
        iyz="-8.26381083889673E-06"
        izz="0.00695225382377171" />
    </inertial>
    <visual>
      <origin
        xyz="0 0 0"
        rpy="0 0 0" />
      <geometry>
        <mesh
          filename="package://orochi7/meshes/Link_1.STL" />
      </geometry>
      <material
        name="">
        <color
          rgba="0.898039215686275 0.917647058823529 0.929411764705882 1" />
      </material>
    </visual>
    <collision>
      <origin
        xyz="0 0 0"
        rpy="0 0 0" />
      <geometry>
        <mesh
          filename="package://orochi7/meshes/Link_1.STL" />
      </geometry>
    </collision>
  </link>
  <joint
    name="joint_1"
    type="revolute">
    <origin
      xyz="0 0 0.23849"
      rpy="0 0 0" />
    <parent
      link="Link_0" />
    <child
      link="Link_1" />
    <axis
      xyz="0 0 1" />
    <limit
      lower="-2.967"
      upper="2.967"
      effort="1000"
      velocity="2" />
  </joint>

<!-- ##########################Link_2########################## -->

  <link
    name="Link_2">
    <inertial>
      <origin
        xyz="4.36134385775678E-05 -0.0969448215522462 0.0240523906851286"
        rpy="0 0 0" />
      <mass
        value="2.30470481838206" />
      <inertia
        ixx="0.0145281343817937"
        ixy="3.77897817051715E-06"
        ixz="1.59621986654239E-06"
        iyy="0.00621283066084087"
        iyz="-0.00239478598373043"
        izz="0.0155561583121572" />
    </inertial>
    <visual>
      <origin
        xyz="0 0 0"
        rpy="0 0 0" />
      <geometry>
        <mesh
          filename="package://orochi7/meshes/Link_2.STL" />
      </geometry>
      <material
        name="">
        <color
          rgba="0.898039215686275 0.917647058823529 0.929411764705882 1" />
      </material>
    </visual>
    <collision>
      <origin
        xyz="0 0 0"
        rpy="0 0 0" />
      <geometry>
        <mesh
          filename="package://orochi7/meshes/Link_2.STL" />
      </geometry>
    </collision>
  </link>
  <joint
    name="joint_2"
    type="revolute">
    <origin
      xyz="0.00024 0 0.161"
      rpy="-1.5708 0 1.5708" />
    <parent
      link="Link_1" />
    <child
      link="Link_2" />
    <axis
      xyz="0 0 1" />
    <limit
      lower="-2.094"
      upper="2.094"
      effort="1000"
      velocity="2" />
  </joint>

<!-- ##########################Link_3########################## -->

  <link
    name="Link_3">
    <inertial>
      <origin
        xyz="0.018048779946475 0.000129409806994231 0.106756804682869"
        rpy="0 0 0" />
      <mass
        value="1.01352215483001" />
      <inertia
        ixx="0.00444118911054174"
        ixy="-2.48194706399251E-06"
        ixz="-0.000457698659442359"
        iyy="0.00389291293176773"
        iyz="-1.33064047944416E-05"
        izz="0.00213921148827011" />
    </inertial>
    <visual>
      <origin
        xyz="0 0 0"
        rpy="0 0 0" />
      <geometry>
        <mesh
          filename="package://orochi7/meshes/Link_3.STL" />
      </geometry>
      <material
        name="">
        <color
          rgba="0.898039215686275 0.917647058823529 0.929411764705882 1" />
      </material>
    </visual>
    <collision>
      <origin
        xyz="0 0 0"
        rpy="0 0 0" />
      <geometry>
        <mesh
          filename="package://orochi7/meshes/Link_3.STL" />
      </geometry>
    </collision>
  </link>
  <joint
    name="joint_3"
    type="revolute">
    <origin
      xyz="2.9731E-05 -0.23575 -0.00062409"
      rpy="1.5708 1.5708 0" />
    <parent
      link="Link_2" />
    <child
      link="Link_3" />
    <axis
      xyz="0 0 1" />
    <limit
      lower="-2.967"
      upper="2.967"
      effort="1000"
      velocity="2" />
  </joint>

<!-- ##########################Link_4########################## -->

  <link
    name="Link_4">
    <inertial>
      <origin
        xyz="5.31189394567101E-06 0.100689878757625 -0.01854742769486"
        rpy="0 0 0" />
      <mass
        value="1.87808667560675" />
      <inertia
        ixx="0.0103397145130341"
        ixy="2.51804015290146E-07"
        ixz="-5.76016285909608E-08"
        iyy="0.00359399190823215"
        iyz="-0.00169270806100584"
        izz="0.0105901135679184" />
    </inertial>
    <visual>
      <origin
        xyz="0 0 0"
        rpy="0 0 0" />
      <geometry>
        <mesh
          filename="package://orochi7/meshes/Link_4.STL" />
      </geometry>
      <material
        name="">
        <color
          rgba="0.898039215686275 0.917647058823529 0.929411764705882 1" />
      </material>
    </visual>
    <collision>
      <origin
        xyz="0 0 0"
        rpy="0 0 0" />
      <geometry>
        <mesh
          filename="package://orochi7/meshes/Link_4.STL" />
      </geometry>
    </collision>
  </link>
  <joint
    name="joint_4"
    type="revolute">
    <origin
      xyz="-0.00011409 -3.235E-05 0.16375"
      rpy="1.5708 0 1.5708" />
    <parent
      link="Link_3" />
    <child
      link="Link_4" />
    <axis
      xyz="0 0 -1" />
    <limit
      lower="-2.094"
      upper="2.094"
      effort="1000"
      velocity="2" />
  </joint>

<!-- ##########################Link_5########################## -->

  <link
    name="Link_5">
    <inertial>
      <origin
        xyz="0.0194131556776644 -4.28172832716598E-05 -0.107325643866726"
        rpy="0 0 0" />
      <mass
        value="0.892428647320994" />
      <inertia
        ixx="0.00338370651671834"
        ixy="-5.50969359424124E-07"
        ixz="0.000365304335885818"
        iyy="0.00301833489256761"
        iyz="-2.20632524303577E-06"
        izz="0.00135669086771338" />
    </inertial>
    <visual>
      <origin
        xyz="0 0 0"
        rpy="0 0 0" />
      <geometry>
        <mesh
          filename="package://orochi7/meshes/Link_5.STL" />
      </geometry>
      <material
        name="">
        <color
          rgba="0.898039215686275 0.917647058823529 0.929411764705882 1" />
      </material>
    </visual>
    <collision>
      <origin
        xyz="0 0 0"
        rpy="0 0 0" />
      <geometry>
        <mesh
          filename="package://orochi7/meshes/Link_5.STL" />
      </geometry>
    </collision>
  </link>
  <joint
    name="joint_5"
    type="revolute">
    <origin
      xyz="-2.9588E-05 0.22974 -0.00010578"
      rpy="1.5708 -1.5708 0" />
    <parent
      link="Link_4" />
    <child
      link="Link_5" />
    <axis
      xyz="0 0 -1" />
    <limit
      lower="-2.967"
      upper="2.967"
      effort="1000"
      velocity="2" />
  </joint>

<!-- ##########################Link_6########################## -->

  <link
    name="Link_6">
    <inertial>
      <origin
        xyz="1.376E-05 -0.04188 0.027899"
        rpy="0 0 0" />
      <mass
        value="2.3887" />
      <inertia
        ixx="0.0090274"
        ixy="2.9426E-06"
        ixz="-2.0317E-06"
        iyy="0.0030811"
        iyz="-0.0016392"
        izz="0.009105" />
    </inertial>
    <visual>
      <origin
        xyz="0 0 0"
        rpy="0 0 0" />
      <geometry>
        <mesh
          filename="package://orochi7/meshes/Link_6.STL" />
      </geometry>
      <material
        name="">
        <color
          rgba="0.89804 0.91765 0.92941 1" />
      </material>
    </visual>
    <collision>
      <origin
        xyz="0 0 0"
        rpy="0 0 0" />
      <geometry>
        <mesh
          filename="package://orochi7/meshes/Link_6.STL" />
      </geometry>
    </collision>
  </link>
  <joint
    name="joint_6"
    type="revolute">
    <origin
      xyz="0.0026058 -3.2208E-05 -0.15975"
      rpy="1.5708 0 -1.5708" />
    <parent
      link="Link_5" />
    <child
      link="Link_6" />
    <axis
      xyz="0 0 -1" />
    <limit
      lower="-2.094"
      upper="2.094"
      effort="1000"
      velocity="2" />
  </joint>

<!-- ##########################Link_7########################## -->

  <link
    name="Link_7">
    <inertial>
      <origin
        xyz="4.02145722769179E-06 4.01778957818443E-06 0.0075636449697063"
        rpy="0 0 0" />
      <mass
        value="0.225884416364818" />
      <inertia
        ixx="0.000104188659613568"
        ixy="7.81396930623823E-09"
        ixz="-1.39484791249742E-08"
        iyy="0.000104188604048643"
        iyz="-1.39362927624144E-08"
        izz="0.000193927698384735" />
    </inertial>
    <visual>
      <origin
        xyz="0 0 0"
        rpy="0 0 0" />
      <geometry>
        <mesh
          filename="package://orochi7/meshes/Link_7.STL" />
      </geometry>
      <material
        name="">
        <color
          rgba="0.898039215686275 0.917647058823529 0.929411764705882 1" />
      </material>
    </visual>
    <collision>
      <origin
        xyz="0 0 0"
        rpy="0 0 0" />
      <geometry>
        <mesh
          filename="package://orochi7/meshes/Link_7.STL" />
      </geometry>
    </collision>
  </link>
  <joint
    name="joint_7"
    type="revolute">
    <origin
      xyz="0 -0.1845 0.00175"
      rpy="1.5708 1.5708 0" />
    <parent
      link="Link_6" />
    <child
      link="Link_7" />
    <axis
      xyz="0 0 -1" />
    <limit
      lower="-3.054"
      upper="3.054"
      effort="1000"
      velocity="2" />
  </joint>

<!-- /////////////////////////////////   Gazebo   ////////////////////////////////////// -->
  <gazebo reference="base_link">
      <material>Gazebo/White</material>
  </gazebo>
  <gazebo reference="Link_0">
      <material>Gazebo/White</material>
  </gazebo>
  <gazebo reference="Link_1">
      <material>Gazebo/White</material>
  </gazebo>
  <gazebo reference="Link_2">
      <material>Gazebo/White</material>
  </gazebo>
  <gazebo reference="Link_3">
      <material>Gazebo/White</material>
  </gazebo>
  <gazebo reference="Link_4">
      <material>Gazebo/White</material>
  </gazebo>
  <gazebo reference="Link_5">
      <material>Gazebo/White</material>
  </gazebo>
  <gazebo reference="Link_6">
      <material>Gazebo/White</material>
  </gazebo>
  <gazebo reference="Link_7">
      <material>Gazebo/White</material>
  </gazebo>

<!-- Transmissions for ROS Control -->
  <xacro:macro name="transmission_block" params="joint_name">
      <transmission name="${joint_name}_trans">
          <type>transmission_interface/SimpleTransmission</type>
          <joint name="${joint_name}">
              <hardwareInterface>hardware_interface/PositionJointInterface</hardwareInterface>
          </joint>
          <actuator name="{joint_name}_motor">
              <hardwareInterface>hardware_interface/PositionJointInterface</hardwareInterface>
              <mechanicalReduction>1</mechanicalReduction>
          </actuator>
      </transmission>
  </xacro:macro>
    
  <xacro:transmission_block joint_name="joint_1"/>
  <xacro:transmission_block joint_name="joint_2"/>
  <xacro:transmission_block joint_name="joint_3"/>
  <xacro:transmission_block joint_name="joint_4"/>
  <xacro:transmission_block joint_name="joint_5"/>
  <xacro:transmission_block joint_name="joint_6"/>
  <xacro:transmission_block joint_name="joint_7"/>

<!-- ros_control plugin -->
  <gazebo>
      <plugin name="gazebo_ros_control" filename="libgazebo_ros_control.so">
          <robotNamespace>/orochi</robotNamespace>
          <legacyModeNS>true</legacyModeNS>
      </plugin>
  </gazebo>

</robot>




